Workbook

Sheet 说明
A1: 项目 | B1: 说明
A2: 数据基准 | B2: 2026-10-23；远端022237df当前文件；554条总记录、426条纳入范围，分类/人工证据保留；缺全文不改变范围。
A3: JCR年份 | B3: 统一使用2024指标年，对应2025发布版。依据Clarivate 2025 Release Notes；本表不声称使用2026发布版。
A4: JCR定义 | B4: 使用JIF Quartile（Q1–Q4）。不使用中科院分区、SJR/SCImago/CiteScore或影响因子高低替代JCR分区。
A5: 核验来源与限制 | B5: 主要为武汉大学图书馆机构JCR期刊信息/列表的搜索索引摘录，逐刊保留年份、ISSN、学科、分区及URL和索引快照；直连页面未成功，未取得Clarivate账户全量导出。仅计已核实学科，所有未知留空/待核实。
A6: 两种Q1口径 | B6: 至少一个已核实学科Q1；全部已核实学科均Q1。后者不承诺没有尚未显示的学科，需完整JCR导出补足。
A7: 分母 | B7: 纳入范围内的目标期刊论文；分别按全部目标和已核实JCR分区目标为分母。学位、会议、海报、书章及类型待核实条目单列；未知JCR不作非Q1。
A8: Q1数量性质 | B8: 可核验部分的已确认数量/下限；不是完整JCR覆盖下的最终总数。分区是2024年期刊特征，不是每篇论文发表当年的历史分区。
A9: 还需要的JCR导出 | B9: 请提供2025发布版、2024指标年的JCR Excel/CSV，含Journal name、ISSN、eISSN、全部Category、JIF Quartile、JIF Rank、JCR Year、导出日期。期刊名单见期刊汇总及待核实项。
A10: 原件与附件 | B10: 665个不同字节对象；全文402文件组合388篇；154件原格式科研补充材料（含3 ZIP），5 ZIP派生成员不重复计数。61件附件唯一关联尚待核实。
A11: 异常处理 | B11: 4个上传正文身份冲突、13不同字节历史候选、1作者变更表保留，不计目标全文；R13964误放同字节附件已归R13834并留映射。
A12: main清理 | B12: 保全b739c0e后独立读回30原件全部通过，再正常提交0bdf0b9清理main；README原字节不变；旧副本仍在Git历史。
... A14: 官方多学科/JIF分区说明 | B14: https://journalcitationreports.zendesk.com/hc/en-gb/articles/28351430970001-Journal-Profile

Sheet 文献明细
A1: 文献ID | B1: 题名 | C1: 年份 | D1: 原总表年份 | E1: DOI | F1: 文献类型 | G1: 现有研究分类 | H1: 纳入范围 | I1: 统计文献组 | J1: 是否目标期刊论文 | K1: 期刊 | L1: 原期刊字段 | M1: ISSN | N1: eISSN | O1: 正文获取状态 | P1: 核验全文标志 | Q1: 补充材料状态 | R1: JCR数据年份 | S1: JCR发布版本 | T1: 学科类别 | U1: JIF分区（逐学科） | V1: 至少一学科Q1 | W1: 全部已核实学科均Q1 | X1: JCR分区已核实 | Y1: 查询来源 | Z1: 期刊身份来源 | AA1: 核验备注 | AB1: 正文全部规范路径 | AC1: 补充材料路径 | AD1: 正文GitHub链接
A2: R00313 | B2: Molecular analysis of the biomass of a fluidized bed reactor treating synthetic vinasse at anaerobic and micro-aerobic conditions | C2: 2012 | D2: 2012 | E2: 10.1007/s00253-011-3529-3 | F2: 期刊文章 | G2: 1 直接向 AD 反应器或内部循环系统供氧 | H2: 是 | I2: 研究类 | J2: 是 | K2: APPLIED MICROBIOLOGY AND BIOTECHNOLOGY | L2: Applied Microbiology and Biotechnology | M2: 0175-7598 | N2: 1432-0614 | O2: 已取得核验全文 | P2: 是 | Q2: 当前无补充材料原件；沿用既有缺失/无附件证据，不据此认定无附件 | R2: 2024 | S2: 2025发布版（2024指标年） | T2: BIOTECHNOLOGY & APPLIED MICROBIOLOGY | U2: BIOTECHNOLOGY & APPLIED MICROBIOLOGY: Q1 | V2: 是 | W2: 是 | X2: 是 | Y2: https://topj.lib.whu.edu.cn/searchxk1.asp?ordertype=asc&page=6&q=&xk=291 | Z2: https://api.crossref.org/works/10.1007/s00253-011-3529-3 | AA2: 机构2024年JCR列表栏：搜索索引可核验；原页直连未成功；仅统计已显示学科 | 全部Q1仅指本表全部已核实学科；无官方完整学科导出，不承诺没有未显示学科 | AB2: original_files/R00313/fulltext/fulltext__published__67968c41f5ab39d0.pdf | AD2: https://github.com/Colliam-Vermilion/FirstCodex/blob/results/ad-oxygen-literature-20261006/results/ad-oxygen-literature-20261006/original_files/R00313/fulltext/fulltext__published__67968c41f5ab39d0.pdf
A3: R00379 | B3: Robustness of the microaerobic removal of hydrogen sulfide from biogas | C3: 2012 | D3: 2012 | E3: 10.2166/wst.2012.013 | F3: 期刊文章 | G3: 1 直接向 AD 反应器或内部循环系统供氧 | H3: 是 | I3: 研究类 | J3: 是 | K3: WATER SCIENCE AND TECHNOLOGY | L3: Water Science and Technology | M3: 0273-1223 | N3: 1996-9732 | O3: 已取得核验全文 | P3: 是 | Q3: 当前无补充材料原件；沿用既有缺失/无附件证据，不据此认定无附件 | R3: 2024 | S3: 2025发布版（2024指标年） | T3: WATER RESOURCES; ENGINEERING, ENVIRONMENTAL; ENVIRONMENTAL SCIENCES | U3: WATER RESOURCES: Q2; ENGINEERING, ENVIRONMENTAL: Q3; ENVIRONMENTAL SCIENCES: Q3 | V3: 否 | W3: 否 | X3: 是 | Y3: https://topj.lib.whu.edu.cn/search2.asp?ordertype=&page=2&q=&sea=w&searchtype=esi | Z3: https://api.crossref.org/works/10.2166/wst.2012.013 | AA3: 机构2024年JCR列表栏：搜索索引可核验；原页直连未成功；仅统计已显示学科 | 全部Q1仅指本表全部已核实学科；无官方完整学科导出，不承诺没有未显示学科 | AB3: original_files/R00379/fulltext/fulltext__published__4f8df7de0de247c6.pdf | AD3: https://github.com/Colliam-Vermilion/FirstCodex/blob/results/ad-oxygen-literature-20261006/results/ad-oxygen-literature-20261006/original_files/R00379/fulltext/fulltext__published__4f8df7de0de247c6.pdf
A4: R00430 | B4: The role of the headspace in hydrogen sulfide removal during microaerobic digestion of sludge | C4: 2012 | D4: 2012 | E4: 10.2166/wst.2012.457 | F4: 期刊文章 | G4: 1 直接向 AD 反应器或内部循环系统供氧 | H4: 是 | I4: 研究类 | J4: 是 | K4: WATER SCIENCE AND TECHNOLOGY | L4: Water Science and Technology | M4: 0273-1223 | N4: 1996-9732 | O4: 已取得核验全文 | P4: 是 | Q4: 当前无补充材料原件；沿用既有缺失/无附件证据，不据此认定无附件 | R4: 2024 | S4: 2025发布版（2024指标年） | T4: WATER RESOURCES; ENGINEERING, ENVIRONMENTAL; ENVIRONMENTAL SCIENCES | U4: WATER RESOURCES: Q2; ENGINEERING, ENVIRONMENTAL: Q3; ENVIRONMENTAL SCIENCES: Q3 | V4: 否 | W4: 否 | X4: 是 | Y4: https://topj.lib.whu.edu.cn/search2.asp?ordertype=&page=2&q=&sea=w&searchtype=esi | Z4: https://api.crossref.org/works/10.2166/wst.2012.457 | AA4: 机构2024年JCR列表栏：搜索索引可核验；原页直连未成功；仅统计已显示学科 | 全部Q1仅指本表全部已核实学科；无官方完整学科导出，不承诺没有未显示学科 | AB4: original_files/R00430/fulltext/fulltext__published__bac7ef01cee02f8e.pdf | AD4: https://github.com/Colliam-Vermilion/FirstCodex/blob/results/ad-oxygen-literature-20261006/results/ad-oxygen-literature-20261006/original_files/R00430/fulltext/fulltext__published__bac7ef01cee02f8e.pdf
A5: R00651 | B5: Effect of micro-aeration on anaerobic digestion of primary sludge under septic tank conditions | C5: 2013 | D5: 2013 | E5: 10.1007/s00449-012-0798-x | F5: 期刊文章 | G5: 1 直接向 AD 反应器或内部循环系统供氧 | H5: 是 | I5: 研究类 | J5: 是 | K5: BIOPROCESS AND BIOSYSTEMS ENGINEERING | L5: Bioprocess and Biosystems Engineering | M5: 1615-7591 | N5: 1615-7605 | O5: 已取得核验全文 | P5: 是 | Q5: 当前无补充材料原件；沿用既有缺失/无附件证据，不据此认定无附件 | R5: 2024 | S5: 2025发布版（2024指标年） | T5: BIOTECHNOLOGY & APPLIED MICROBIOLOGY; ENGINEERING, CHEMICAL | U5: BIOTECHNOLOGY & APPLIED MICROBIOLOGY: Q2; ENGINEERING, CHEMICAL: Q2 | V5: 否 | W5: 否 | X5: 是 | Y5: https://topj.lib.whu.edu.cn/show.asp?cat=sci&id=5879 | Z5: https://api.crossref.org/works/10.1007/s00449-012-0798-x | AA5: 机构JCR栏：搜索索引可核验；原页面直连未成功；非Clarivate账户导出 | 全部Q1仅指本表全部已核实学科；无官方完整学科导出，不承诺没有未显示学科 | AB5: original_files/R00651/fulltext/fulltext__published__4a05c2b25035cc74.pdf | AD5: https://github.com/Colliam-Vermilion/FirstCodex/blob/results/ad-oxygen-literature-20261006/results/ad-oxygen-literature-20261006/original_files/R00651/fulltext/fulltext__published__4a05c2b25035cc74.pdf
A6: R00735 | B6: Improvement of Anaerobic Digester Performance by Wastewater Recirculation through an Aerated Membrane | C6: 2013 | D6: 2013 | E6: 10.13031/trans.56.9869 | F6: 期刊文章 | G6: 1 直接向 AD 反应器或内部循环系统供氧 | H6: 是 | I6: 研究类 | J6: 是 | K6: Transactions of the ASABE | L6: Transactions of the ASABE | M6: 2151-0032 | N6: 2151-0040 | O6: 未取得全文 | P6: 否 | Q6: 当前无补充材料原件；沿用既有缺失/无附件证据，不据此认定无附件 | R6: 2024 | S6: 2025发布版（2024指标年） | V6: 待核实 | W6: 待核实 | X6: 否 | Z6: https://api.crossref.org/works/10.13031/trans.56.9869 | AA6: 2024指标年JCR分区未核实；空白不能当非Q1。需要2025发布版/2024指标年的JCR全部学科导出。
A7: R00795 | B7: Microaerobic desulphurisation unit: A new biological system for the removal of H2S from biogas | C7: 2013 | D7: 2013 | E7: 10.1016/j.biortech.2013.05.084 | F7: 期刊文章 | G7: 1 直接向 AD 反应器或内部循环系统供氧 | H7: 是 | I7: 研究类 | J7: 是 | K7: BIORESOURCE TECHNOLOGY | L7: Bioresource Technology | M7: 0960-8524 | O7: 已取得核验全文 | P7: 是 | Q7: 当前无补充材料原件；沿用既有缺失/无附件证据，不据此认定无附件 | R7: 2024 | S7: 2025发布版（2024指标年） | T7: AGRICULTURAL ENGINEERING; BIOTECHNOLOGY & APPLIED MICROBIOLOGY; ENERGY & FUELS | U7: AGRICULTURAL ENGINEERING: Q1; BIOTECHNOLOGY & APPLIED MICROBIOLOGY: Q1; ENERGY & FUELS: Q1 | V7: 是 | W7: 是 | X7: 是 | Y7: https://topj.lib.whu.edu.cn/show.asp?cat=zk&id=3976 | Z7: https://api.crossref.org/works/10.1016/j.biortech.2013.05.084 | AA7: 机构JCR栏：搜索索引可核验；原页面直连未成功；非Clarivate账户导出 | 全部Q1仅指本表全部已核实学科；无官方完整学科导出，不承诺没有未显示学科 | AB7: original_files/R00795/fulltext/fulltext__published__874efe69f8123943.pdf | AD7: https://github.com/Colliam-Vermilion/FirstCodex/blob/results/ad-oxygen-literature-20261006/results/ad-oxygen-literature-20261006/original_files/R00795/fulltext/fulltext__published__874efe69f8123943.pdf
A8: R01297 | B8: Improving products of anaerobic sludge digestion by microaeration | C8: 2014 | D8: 2014 | E8: 10.2166/wst.2013.779 | F8: 期刊文章 | G8: 1 直接向 AD 反应器或内部循环系统供氧 | H8: 是 | I8: 研究类 | J8: 是 | K8: WATER SCIENCE AND TECHNOLOGY | L8: Water Science and Technology | M8: 0273-1223 | N8: 1996-9732 | O8: 已取得核验全文 | P8: 是 | Q8: 当前无补充材料原件；沿用既有缺失/无附件证据，不据此认定无附件 | R8: 2024 | S8: 2025发布版（2024指标年） | T8: WATER RESOURCES; ENGINEERING, ENVIRONMENTAL; ENVIRONMENTAL SCIENCES | U8: WATER RESOURCES: Q2; ENGINEERING, ENVIRONMENTAL: Q3; ENVIRONMENTAL SCIENCES: Q3 | V8: 否 | W8: 否 | X8: 是 | Y8: https://topj.lib.whu.edu.cn/search2.asp?ordertype=&page=2&q=&sea=w&searchtype=esi | Z8: https://api.crossref.org/works/10.2166/wst.2013.779 | AA8: 机构2024年JCR列表栏：搜索索引可核验；原页直连未成功；仅统计已显示学科 | 全部Q1仅指本表全部已核实学科；无官方完整学科导出，不承诺没有未显示学科 | AB8: original_files/R01297/fulltext/fulltext__published__de7ffcf910e42cc3.pdf | AD8: https://github.com/Colliam-Vermilion/FirstCodex/blob/results/ad-oxygen-literature-20261006/results/ad-oxygen-literature-20261006/original_files/R01297/fulltext/fulltext__published__de7ffcf910e42cc3.pdf
A9: R01347 | B9: Microaeration for hydrogen sulfide removal in UASB reactor | C9: 2014 | D9: 2014 | E9: 10.1016/j.biortech.2014.09.056 | F9: 期刊文章 | G9: 1 直接向 AD 反应器或内部循环系统供氧 | H9: 是 | I9: 研究类 | J9: 是 | K9: BIORESOURCE TECHNOLOGY | L9: Bioresource Technology | M9: 0960-8524 | O9: 已取得核验全文 | P9: 是 | Q9: 当前无补充材料原件；沿用既有缺失/无附件证据，不据此认定无附件 | R9: 2024 | S9: 2025发布版（2024指标年） | T9: AGRICULTURAL ENGINEERING; BIOTECHNOLOGY & APPLIED MICROBIOLOGY; ENERGY & FUELS | U9: AGRICULTURAL ENGINEERING: Q1; BIOTECHNOLOGY & APPLIED MICROBIOLOGY: Q1; ENERGY & FUELS: Q1 | V9: 是 | W9: 是 | X9: 是 | Y9: https://topj.lib.whu.edu.cn/show.asp?cat=zk&id=3976 | Z9: https://api.crossref.org/works/10.1016/j.biortech.2014.09.056 | AA9: 机构JCR栏：搜索索引可核验；原页面直连未成功；非Clarivate账户导出 | 全部Q1仅指本表全部已核实学科；无官方完整学科导出，不承诺没有未显示学科 | AB9: original_files/R01347/fulltext/fulltext__published__45f836aff9088c2e.pdf | AD9: https://github.com/Colliam-Vermilion/FirstCodex/blob/results/ad-oxygen-literature-20261006/results/ad-oxygen-literature-20261006/original_files/R01347/fulltext/fulltext__published__45f836aff9088c2e.pdf
A10: R01350 | B10: Microaerobic digestion of sewage sludge on an industrial-pilot scale: The efficiency of biogas desulphurisation under different configurations and the impact of O2 on the microbial communities | C10: 2014 | D10: 2014 | E10: 10.1016/j.biortech.2014.04.109 | F10: 期刊文章 | G10: 1 直接向 AD 反应器或内部循环系统供氧 | H10: 是 | I10: 研究类 | J10: 是 | K10: BIORESOURCE TECHNOLOGY | L10: Bioresource Technology | M10: 0960-8524 | O10: 已取得核验全文 | P10: 是 | Q10: 当前无补充材料原件；沿用既有缺失/无附件证据，不据此认定无附件 | R10: 2024 | S10: 2025发布版（2024指标年） | T10: AGRICULTURAL ENGINEERING; BIOTECHNOLOGY & APPLIED MICROBIOLOGY; ENERGY & FUELS | U10: AGRICULTURAL ENGINEERING: Q1; BIOTECHNOLOGY & APPLIED MICROBIOLOGY: Q1; ENERGY & FUELS: Q1 | V10: 是 | W10: 是 | X10: 是 | Y10: https://topj.lib.whu.edu.cn/show.asp?cat=zk&id=3976 | Z10: https://api.crossref.org/works/10.1016/j.biortech.2014.04.109 | AA10: 机构JCR栏：搜索索引可核验；原页面直连未成功；非Clarivate账户导出 | 全部Q1仅指本表全部已核实学科；无官方完整学科导出，不承诺没有未显示学科 | AB10: original_files/R01350/fulltext/fulltext__published__a2d149d39c1e69ee.pdf | AD10: https://github.com/Colliam-Vermilion/FirstCodex/blob/results/ad-oxygen-literature-20261006/results/ad-oxygen-literature-20261006/original_files/R01350/fulltext/fulltext__published__a2d149d39c1e69ee.pdf
A11: R01414 | B11: Oxidation reduction potential as a parameter to regulate micro-oxygen injection into anaerobic digester for reducing hydrogen sulphide concentration in biogas | C11: 2014 | D11: 2014 | E11: 10.1016/j.biortech.2014.09.052 | F11: 期刊文章 | G11: 1 直接向 AD 反应器或内部循环系统供氧 | H11: 是 | I11: 研究类 | J11: 是 | K11: BIORESOURCE TECHNOLOGY | L11: Bioresource Technology | M11: 0960-8524 | O11: 已取得核验全文 | P11: 是 | Q11: 已取得1件原格式补充材料；其中0件唯一关联待核实；完整性未确认 | R11: 2024 | S11: 2025发布版（2024指标年） | T11: AGRICULTURAL ENGINEERING; BIOTECHNOLOGY & APPLIED MICROBIOLOGY; ENERGY & FUELS | U11: AGRICULTURAL ENGINEERING: Q1; BIOTECHNOLOGY & APPLIED MICROBIOLOGY: Q1; ENERGY & FUELS: Q1 | V11: 是 | W11: 是 | X11: 是 | Y11: https://topj.lib.whu.edu.cn/show.asp?cat=zk&id=3976 | Z11: https://api.crossref.org/works/10.1016/j.biortech.2014.09.052 | AA11: 机构JCR栏：搜索索引可核验；原页面直连未成功；非Clarivate账户导出 | 全部Q1仅指本表全部已核实学科；无官方完整学科导出，不承诺没有未显示学科 | AB11: original_files/R01414/fulltext/fulltext__published__f3fdd6d92cc6ded3.pdf | AC11: original_files/R01414/supplementary/supplementary__0b2884c05d320076.docx | AD11: https://github.com/Colliam-Vermilion/FirstCodex/blob/results/ad-oxygen-literature-20261006/results/ad-oxygen-literature-20261006/original_files/R01414/fulltext/fulltext__published__f3fdd6d92cc6ded3.pdf
A12: R01505 | B12: The headspace of microaerobic reactors: Sulphide-oxidising population and the impact of cleaning on the efficiency of biogas desulphurisation | C12: 2014 | D12: 2014 | E12: 10.1016/j.biortech.2014.02.001 | F12: 期刊文章 | G12: 1 直接向 AD 反应器或内部循环系统供氧 | H12: 是 | I12: 研究类 | J12: 是 | K12: BIORESOURCE TECHNOLOGY | L12: Bioresource Technology | M12: 0960-8524 | O12: 已取得核验全文 | P12: 是 | Q12: 当前无补充材料原件；沿用既有缺失/无附件证据，不据此认定无附件 | R12: 2024 | S12: 2025发布版（2024指标年） | T12: AGRICULTURAL ENGINEERING; BIOTECHNOLOGY & APPLIED MICROBIOLOGY; ENERGY & FUELS | U12: AGRICULTURAL ENGINEERING: Q1; BIOTECHNOLOGY & APPLIED MICROBIOLOGY: Q1; ENERGY & FUELS: Q1 | V12: 是 | W12: 是 | X12: 是 | Y12: https://topj.lib.whu.edu.cn/show.asp?cat=zk&id=3976 | Z12: https://api.crossref.org/works/10.1016/j.biortech.2014.02.001 | AA12: 机构JCR栏：搜索索引可核验；原页面直连未成功；非Clarivate账户导出 | 全部Q1仅指本表全部已核实学科；无官方完整学科导出，不承诺没有未显示学科 | AB12: original_files/R01505/fulltext/fulltext__published__cd661b225d80e30c.pdf | AD12: https://github.com/Colliam-Vermilion/FirstCodex/blob/results/ad-oxygen-literature-20261006/results/ad-oxygen-literature-20261006/original_files/R01505/fulltext/fulltext__published__cd661b225d80e30c.pdf
A13: R01556 | B13: Where does the removal of H2S from biogas occur in microaerobic reactors? | C13: 2014 | D13: 2014 | E13: 10.1016/j.biortech.2014.05.058 | F13: 期刊文章 | G13: 1 直接向 AD 反应器或内部循环系统供氧 | H13: 是 | I13: 研究类 | J13: 是 | K13: BIORESOURCE TECHNOLOGY | L13: Bioresource Technology | M13: 0960-8524 | O13: 已取得核验全文 | P13: 是 | Q13: 当前无补充材料原件；沿用既有缺失/无附件证据，不据此认定无附件 | R13: 2024 | S13: 2025发布版（2024指标年） | T13: AGRICULTURAL ENGINEERING; BIOTECHNOLOGY & APPLIED MICROBIOLOGY; ENERGY & FUELS | U13: AGRICULTURAL ENGINEERING: Q1; BIOTECHNOLOGY & APPLIED MICROBIOLOGY: Q1; ENERGY & FUELS: Q1 | V13: 是 | W13: 是 | X13: 是 | Y13: https://topj.lib.whu.edu.cn/show.asp?cat=zk&id=3976 | Z13: https://api.crossref.org/works/10.1016/j.biortech.2014.05.058 | AA13: 机构JCR栏：搜索索引可核验；原页面直连未成功；非Clarivate账户导出 | 全部Q1仅指本表全部已核实学科；无官方完整学科导出，不承诺没有未显示学科 | AB13: original_files/R01556/fulltext/fulltext__published__2f7462391b5df844.pdf | AD13: https://github.com/Colliam-Vermilion/FirstCodex/blob/results/ad-oxygen-literature-20261006/results/ad-oxygen-literature-20261006/original_files/R01556/fulltext/fulltext__published__2f7462391b5df844.pdf
A14: R01654 | B14: Anaerobic digestion of waste biomass from the production of L-cystine in suspended-growth bioreactors | C14: 2015 | D14: 2015 | E14: 10.2166/wst.2015.224 | F14: 期刊文章 | G14: 1 直接向 AD 反应器或内部循环系统供氧 | H14: 是 | I14: 研究类 | J14: 是 | K14: WATER SCIENCE AND TECHNOLOGY | L14: Water Science and Technology | M14: 0273-1223 | O14: 已取得核验全文 | P14: 是 | Q14: 当前无补充材料原件；沿用既有缺失/无附件证据，不据此认定无附件 | R14: 2024 | S14: 2025发布版（2024指标年） | T14: WATER RESOURCES; ENGINEERING, ENVIRONMENTAL; ENVIRONMENTAL SCIENCES | U14: WATER RESOURCES: Q2; ENGINEERING, ENVIRONMENTAL: Q3; ENVIRONMENTAL SCIENCES: Q3 | V14: 否 | W14: 否 | X14: 是 | Y14: https://topj.lib.whu.edu.cn/search2.asp?ordertype=&page=2&q=&sea=w&searchtype=esi | AA14: 既有DOI未由Crossref返回可用元数据（可能为DataCite/JaLC等）；不据此否认记录身份 | 机构2024年JCR列表栏：搜索索引可核验；原页直连未成功；仅统计已显示学科 | 全部Q1仅指本表全部已核实学科；无官方完整学科导出，不承诺没有未显示学科 | AB14: original_files/R01654/fulltext/fulltext__published__07361dc13d0f4990.pdf | AD14: https://github.com/Colliam-Vermilion/FirstCodex/blob/results/ad-oxygen-literature-20261006/results/ad-oxygen-literature-20261006/original_files/R01654/fulltext/fulltext__published__07361dc13d0f4990.pdf
A15: R01785 | B15: Economic analysis of microaerobic removal of H2S from biogas in full-scale sludge digesters | C15: 2015 | D15: 2015 | E15: 10.1016/j.biortech.2015.05.048 | F15: 期刊文章 | G15: 1 直接向 AD 反应器或内部循环系统供氧 | H15: 是 | I15: 研究类 | J15: 是 | K15: BIORESOURCE TECHNOLOGY | L15: Bioresource Technology | M15: 0960-8524 | O15: 已取得核验全文 | P15: 是 | Q15: 当前无补充材料原件；沿用既有缺失/无附件证据，不据此认定无附件 | R15: 2024 | S15: 2025发布版（2024指标年） | T15: AGRICULTURAL ENGINEERING; BIOTECHNOLOGY & APPLIED MICROBIOLOGY; ENERGY & FUELS | U15: AGRICULTURAL ENGINEERING: Q1; BIOTECHNOLOGY & APPLIED MICROBIOLOGY: Q1; ENERGY & FUELS: Q1 | V15: 是 | W15: 是 | X15: 是 | Y15: https://topj.lib.whu.edu.cn/show.asp?cat=zk&id=3976 | Z15: https://api.crossref.org/works/10.1016/j.biortech.2015.05.048 | AA15: 机构JCR栏：搜索索引可核验；原页面直连未成功；非Clarivate账户导出 | 全部Q1仅指本表全部已核实学科；无官方完整学科导出，不承诺没有未显示学科 | AB15: original_files/R01785/fulltext/fulltext__published__1045800466e6b5e7.pdf | AD15: https://github.com/Colliam-Vermilion/FirstCodex/blob/results/ad-oxygen-literature-20261006/results/ad-oxygen-literature-20261006/original_files/R01785/fulltext/fulltext__published__1045800466e6b5e7.pdf
A16: R01911 | B16: Improvement by Micro-Aeration of Anaerobic Digestion of Slaughterhouse Wastewater At 38°C | C16: 2015 | D16: 2015 | E16: 10.15680/ijirset.2015.0403002 | F16: 期刊文章 | G16: 1 直接向 AD 反应器或内部循环系统供氧 | H16: 是 | I16: 研究类 | J16: 是 | K16: International Journal of Innovative Research in Science, Engineering and Technology | L16: International Journal of Innovative Research in Science, Engineering and Technology | M16: 2347-6710 | N16: 2319-8753 | O16: 未取得全文 | P16: 否 | Q16: 当前无补充材料原件；沿用既有缺失/无附件证据，不据此认定无附件 | R16: 2024 | S16: 2025发布版（2024指标年） | V16: 待核实 | W16: 待核实 | X16: 否 | Z16: https://api.crossref.org/works/10.15680/ijirset.2015.0403002 | AA16: 2024指标年JCR分区未核实；空白不能当非Q1。需要2025发布版/2024指标年的JCR全部学科导出。
A17: R02115 | B17: Secondary thermophilic microaerobic treatment in the anaerobic digestion of corn straw | C17: 2015 | D17: 2015 | E17: 10.1016/j.biortech.2015.03.053 | F17: 期刊文章 | G17: 1 直接向 AD 反应器或内部循环系统供氧 | H17: 是 | I17: 研究类 | J17: 是 | K17: BIORESOURCE TECHNOLOGY | L17: Bioresource Technology | M17: 0960-8524 | O17: 已取得核验全文 | P17: 是 | Q17: 当前无补充材料原件；沿用既有缺失/无附件证据，不据此认定无附件 | R17: 2024 | S17: 2025发布版（2024指标年） | T17: AGRICULTURAL ENGINEERING; BIOTECHNOLOGY & APPLIED MICROBIOLOGY; ENERGY & FUELS | U17: AGRICULTURAL ENGINEERING: Q1; BIOTECHNOLOGY & APPLIED MICROBIOLOGY: Q1; ENERGY & FUELS: Q1 | V17: 是 | W17: 是 | X17: 是 | Y17: https://topj.lib.whu.edu.cn/show.asp?cat=zk&id=3976 | Z17: https://api.crossref.org/works/10.1016/j.biortech.2015.03.053 | AA17: 机构JCR栏：搜索索引可核验；原页面直连未成功；非Clarivate账户导出 | 全部Q1仅指本表全部已核实学科；无官方完整学科导出，不承诺没有未显示学科 | AB17: original_files/R02115/fulltext/fulltext__published__e07eece2b7522917.pdf | AD17: https://github.com/Colliam-Vermilion/FirstCodex/blob/results/ad-oxygen-literature-20261006/results/ad-oxygen-literature-20261006/original_files/R02115/fulltext/fulltext__published__e07eece2b7522917.pdf
A18: R02274 | B18: ANAEROBIC DIGESTION OF WASTEWATER WITH HIGH SULFATE CONCENTRATION USING MICRO-AERATION AND NATURAL ZEOLITES | C18: 2016 | D18: 2016 | E18: 10.1590/0104-6632.20160334s20150261 | F18: 期刊文章 | G18: 1 直接向 AD 反应器或内部循环系统供氧 | H18: 是 | I18: 研究类 | J18: 是 | K18: BRAZILIAN JOURNAL OF CHEMICAL ENGINEERING | L18: Brazilian Journal of Chemical Engineering | N18: 0104-6632 | O18: 已取得核验全文 | P18: 是 | Q18: 当前无补充材料原件；沿用既有缺失/无附件证据，不据此认定无附件 | R18: 2024 | S18: 2025发布版（2024指标年） | T18: ENGINEERING, CHEMICAL | U18: ENGINEERING, CHEMICAL: Q3 | V18: 否 | W18: 否 | X18: 是 | Y18: https://topj.lib.whu.edu.cn/show.asp?cat=sci&id=5923 | Z18: https://api.crossref.org/works/10.1590/0104-6632.20160334s20150261 | AA18: 机构JCR栏：搜索索引可核验；原页面直连未成功；非Clarivate账户导出 | 全部Q1仅指本表全部已核实学科；无官方完整学科导出，不承诺没有未显示学科 | AB18: original_files/R02274/fulltext/fulltext__published__4c7da8384f1f6e3d.pdf | AD18: https://github.com/Colliam-Vermilion/FirstCodex/blob/results/ad-oxygen-literature-20261006/results/ad-oxygen-literature-20261006/original_files/R02274/fulltext/fulltext__published__4c7da8384f1f6e3d.pdf
A19: R02454 | B19: Effect of oxygen on the microbial activities of thermophilic anaerobic biomass | C19: 2016 | D19: 2016 | E19: 10.1016/j.biortech.2016.03.085 | F19: 期刊文章 | G19: 1 直接向 AD 反应器或内部循环系统供氧 | H19: 是 | I19: 研究类 | J19: 是 | K19: BIORESOURCE TECHNOLOGY | L19: Bioresource Technology | M19: 0960-8524 | O19: 已取得核验全文 | P19: 是 | Q19: 当前无补充材料原件；沿用既有缺失/无附件证据，不据此认定无附件 | R19: 2024 | S19: 2025发布版（2024指标年） | T19: AGRICULTURAL ENGINEERING; BIOTECHNOLOGY & APPLIED MICROBIOLOGY; ENERGY & FUELS | U19: AGRICULTURAL ENGINEERING: Q1; BIOTECHNOLOGY & APPLIED MICROBIOLOGY: Q1; ENERGY & FUELS: Q1 | V19: 是 | W19: 是 | X19: 是 | Y19: https://topj.lib.whu.edu.cn/show.asp?cat=zk&id=3976 | Z19: https://api.crossref.org/works/10.1016/j.biortech.2016.03.085 | AA19: 机构JCR栏：搜索索引可核验；原页面直连未成功；非Clarivate账户导出 | 全部Q1仅指本表全部已核实学科；无官方完整学科导出，不承诺没有未显示学科 | AB19: original_files/R02454/fulltext/fulltext__published__59977732e1c6bb84.pdf | AD19: https://github.com/Colliam-Vermilion/FirstCodex/blob/results/ad-oxygen-literature-20261006/results/ad-oxygen-literature-20261006/original_files/R02454/fulltext/fulltext__published__59977732e1c6bb84.pdf
A20: R02585 | B20: In situ Removal of Hydrogen Sulfide During Biogas Fermentation at Microaerobic Condition | C20: 2016 | D20: 2016 | E20: 10.1007/s12010-016-2135-3 | F20: 期刊文章 | G20: 1 直接向 AD 反应器或内部循环系统供氧 | H20: 是 | I20: 研究类 | J20: 是 | K20: APPLIED BIOCHEMISTRY AND BIOTECHNOLOGY | L20: Applied Biochemistry and Biotechnology | M20: 0273-2289 | N20: 1559-0291 | O20: 已取得核验全文 | P20: 是 | Q20: 当前无补充材料原件；沿用既有缺失/无附件证据，不据此认定无附件 | R20: 2024 | S20: 2025发布版（2024指标年） | T20: BIOCHEMISTRY & MOLECULAR BIOLOGY; BIOTECHNOLOGY & APPLIED MICROBIOLOGY | U20: BIOCHEMISTRY & MOLECULAR BIOLOGY: Q2; BIOTECHNOLOGY & APPLIED MICROBIOLOGY: Q2 | V20: 否 | W20: 否 | X20: 是 | Y20: https://topj.lib.whu.edu.cn/show.asp?cat=sci&id=2805 | Z20: https://api.crossref.org/works/10.1007/s12010-016-2135-3 | AA20: 机构JCR栏：搜索索引可核验；原页面直连未成功；非Clarivate账户导出 | 全部Q1仅指本表全部已核实学科；无官方完整学科导出，不承诺没有未显示学科 | AB20: original_files/R02585/fulltext/fulltext__published__ece7fec3277a694d.pdf | AD20: https://github.com/Colliam-Vermilion/FirstCodex/blob/results/ad-oxygen-literature-20261006/results/ad-oxygen-literature-20261006/original_files/R02585/fulltext/fulltext__published__ece7fec3277a694d.pdf
A21: R02819 | B21: Technical, Economical, and Microbiological Aspects of the Microaerobic Process on H2S Removal for Low Sulfate Concentration Wastewaters | C21: 2016 | D21: 2016 | E21: 10.1007/s12010-016-2174-9 | F21: 期刊文章 | G21: 1 直接向 AD 反应器或内部循环系统供氧 | H21: 是 | I21: 研究类 | J21: 是 | K21: APPLIED BIOCHEMISTRY AND BIOTECHNOLOGY | L21: Applied Biochemistry and Biotechnology | M21: 0273-2289 | N21: 1559-0291 | O21: 已取得核验全文 | P21: 是 | Q21: 当前无补充材料原件；沿用既有缺失/无附件证据，不据此认定无附件 | R21: 2024 | S21: 2025发布版（2024指标年） | T21: BIOCHEMISTRY & MOLECULAR BIOLOGY; BIOTECHNOLOGY & APPLIED MICROBIOLOGY | U21: BIOCHEMISTRY & MOLECULAR BIOLOGY: Q2; BIOTECHNOLOGY & APPLIED MICROBIOLOGY: Q2 | V21: 否 | W21: 否 | X21: 是 | Y21: https://topj.lib.whu.edu.cn/show.asp?cat=sci&id=2805 | Z21: https://api.crossref.org/works/10.1007/s12010-016-2174-9 | AA21: 机构JCR栏：搜索索引可核验；原页面直连未成功；非Clarivate账户导出 | 全部Q1仅指本表全部已核实学科；无官方完整学科导出，不承诺没有未显示学科 | AB21: original_files/R02819/fulltext/fulltext__published__bf9c210e52bacc5f.pdf | AD21: https://github.com/Colliam-Vermilion/FirstCodex/blob/results/ad-oxygen-literature-20261006/results/ad-oxygen-literature-20261006/original_files/R02819/fulltext/fulltext__published__bf9c210e52bacc5f.pdf
A22: R03161 | B22: Effect of liquid surface area on hydrogen sulfide oxidation during micro-aeration in dairy manure digesters | C22: 2017 | D22: 2017 | E22: 10.1371/journal.pone.0185738 | F22: 期刊文章 | G22: 1 直接向 AD 反应器或内部循环系统供氧 | H22: 是 | I22: 研究类 | J22: 是 | K22: PLOS ONE | L22: PLOS ONE | N22: 1932-6203 | O22: 已取得核验全文 | P22: 是 | Q22: 已取得1件原格式补充材料；其中0件唯一关联待核实；完整性未确认 | R22: 2024 | S22: 2025发布版（2024指标年） | V22: 待核实 | W22: 待核实 | X22: 否 | Z22: https://api.crossref.org/works/10.1371/journal.pone.0185738 | AA22: 2024指标年JCR分区未核实；空白不能当非Q1。需要2025发布版/2024指标年的JCR全部学科导出。 | AB22: original_files/R03161/fulltext/fulltext__published__ea90043284b5a305.pdf | AC22: original_files/R03161/supplementary/supplementary__d7cc276f64fa4c14.xlsx | AD22: https://github.com/Colliam-Vermilion/FirstCodex/blob/results/ad-oxygen-literature-20261006/results/ad-oxygen-literature-20261006/original_files/R03161/fulltext/fulltext__published__ea90043284b5a305.pdf
A23: R03164 | B23: Effect of micro-aeration and inoculum type on the biodegradation of lignocellulosic substrate | C23: 2017 | D23: 2017 | E23: 10.1016/j.biortech.2016.11.081 | F23: 期刊文章 | G23: 1 直接向 AD 反应器或内部循环系统供氧 | H23: 是 | I23: 研究类 | J23: 是 | K23: BIORESOURCE TECHNOLOGY | L23: Bioresource Technology | M23: 0960-8524 | O23: 已取得核验全文 | P23: 是 | Q23: 当前无补充材料原件；沿用既有缺失/无附件证据，不据此认定无附件 | R23: 2024 | S23: 2025发布版（2024指标年） | T23: AGRICULTURAL ENGINEERING; BIOTECHNOLOGY & APPLIED MICROBIOLOGY; ENERGY & FUELS | U23: AGRICULTURAL ENGINEERING: Q1; BIOTECHNOLOGY & APPLIED MICROBIOLOGY: Q1; ENERGY & FUELS: Q1 | V23: 是 | W23: 是 | X23: 是 | Y23: https://topj.lib.whu.edu.cn/show.asp?cat=zk&id=3976 | Z23: https://api.crossref.org/works/10.1016/j.biortech.2016.11.081 | AA23: 机构JCR栏：搜索索引可核验；原页面直连未成功；非Clarivate账户导出 | 全部Q1仅指本表全部已核实学科；无官方完整学科导出，不承诺没有未显示学科 | AB23: original_files/R03164/fulltext/fulltext__published__948ccf2541317dc8.pdf | AD23: https://github.com/Colliam-Vermilion/FirstCodex/blob/results/ad-oxygen-literature-20261006/results/ad-oxygen-literature-20261006/original_files/R03164/fulltext/fulltext__published__948ccf2541317dc8.pdf
A24: R03455 | B24: Performance evaluation of combining microaerobic desulfurization with addition of rusty scrap iron (RSI) during waste-activated sludge digestion | C24: 2017 | D24: 2017 | E24: 10.5004/dwt.2017.20976 | F24: 期刊文章 | G24: 1 直接向 AD 反应器或内部循环系统供氧 | H24: 是 | I24: 研究类 | J24: 是 | K24: Desalination and Water Treatment | L24: Desalination and Water Treatment | M24: 1944-3986 | O24: 已取得核验全文 | P24: 是 | Q24: 当前无补充材料原件；沿用既有缺失/无附件证据，不据此认定无附件 | R24: 2024 | S24: 2025发布版（2024指标年） | T24: WATER RESOURCES; ENGINEERING, CHEMICAL | U24: WATER RESOURCES: Q4; ENGINEERING, CHEMICAL: Q4 | V24: 否 | W24: 否 | X24: 是 | Y24: https://topj.lib.whu.edu.cn/show.asp?cat=sci&id=5937 | Z24: https://api.crossref.org/works/10.5004/dwt.2017.20976 | AA24: 机构JCR栏：搜索索引可核验；原页面直连未成功；非Clarivate账户导出 | 全部Q1仅指本表全部已核实学科；无官方完整学科导出，不承诺没有未显示学科 | AB24: original_files/R03455/fulltext/fulltext__published__64a8528ddfd93bdf.pdf | AD24: https://github.com/Colliam-Vermilion/FirstCodex/blob/results/ad-oxygen-literature-20261006/results/ad-oxygen-literature-20261006/original_files/R03455/fulltext/fulltext__published__64a8528ddfd93bdf.pdf
A25: R03522 | B25: Simple biogas desulfurization by microaeration – Full scale experience | C25: 2017 | D25: 2017 | E25: 10.1016/j.anaerobe.2017.01.002 | F25: 期刊文章 | G25: 1 直接向 AD 反应器或内部循环系统供氧 | H25: 是 | I25: 研究类 | J25: 是 | K25: Anaerobe | L25: Anaerobe | M25: 1075-9964 | O25: 已取得核验全文 | P25: 是 | Q25: 当前无补充材料原件；沿用既有缺失/无附件证据，不据此认定无附件 | R25: 2024 | S25: 2025发布版（2024指标年） | V25: 待核实 | W25: 待核实 | X25: 否 | Z25: https://api.crossref.org/works/10.1016/j.anaerobe.2017.01.002 | AA25: 2024指标年JCR分区未核实；空白不能当非Q1。需要2025发布版/2024指标年的JCR全部学科导出。 | AB25: original_files/R03522/fulltext/fulltext__published__73e8e5aed501f6e5.pdf | AD25: https://github.com/Colliam-Vermilion/FirstCodex/blob/results/ad-oxygen-literature-20261006/results/ad-oxygen-literature-20261006/original_files/R03522/fulltext/fulltext__published__73e8e5aed501f6e5.pdf
A26: R03564 | B26: The Influence of Micro-Oxygen Addition on Desulfurization Performance and Microbial Communities during Waste-Activated Sludge Digestion in a Rusty Scrap Iron-Loaded Anaerobic Digester | C26: 2017 | D26: 2017 | E26: 10.3390/en10020258 | F26: 期刊文章 | G26: 1 直接向 AD 反应器或内部循环系统供氧 | H26: 是 | I26: 研究类 | J26: 是 | K26: Energies | L26: Energies | N26: 1996-1073 | O26: 已取得核验全文 | P26: 是 | Q26: 当前无补充材料原件；沿用既有缺失/无附件证据，不据此认定无附件 | R26: 2024 | S26: 2025发布版（2024指标年） | V26: 待核实 | W26: 待核实 | X26: 否 | Z26: https://api.crossref.org/works/10.3390/en10020258 | AA26: 2024指标年JCR分区未核实；空白不能当非Q1。需要2025发布版/2024指标年的JCR全部学科导出。 | AB26: original_files/R03564/fulltext/fulltext__published__2f2d17a0a7254275.pdf | AD26: https://github.com/Colliam-Vermilion/FirstCodex/blob/results/ad-oxygen-literature-20261006/results/ad-oxygen-literature-20261006/original_files/R03564/fulltext/fulltext__published__2f2d17a0a7254275.pdf
A27: R03900 | B27: Efficiency, granulation, and bacterial populations related to pollutant removal in an upflow microaerobic sludge reactor treating wastewater with low COD/TN ratio | C27: 2018 | D27: 2018 | E27: 10.1016/j.biortech.2018.08.016 | F27: 期刊文章 | G27: 1 直接向 AD 反应器或内部循环系统供氧 | H27: 是 | I27: 研究类 | J27: 是 | K27: BIORESOURCE TECHNOLOGY | L27: Bioresource Technology | M27: 0960-8524 | O27: 已取得核验全文 | P27: 是 | Q27: 当前无补充材料原件；沿用既有缺失/无附件证据，不据此认定无附件 | R27: 2024 | S27: 2025发布版（2024指标年） | T27: AGRICULTURAL ENGINEERING; BIOTECHNOLOGY & APPLIED MICROBIOLOGY; ENERGY & FUELS | U27: AGRICULTURAL ENGINEERING: Q1; BIOTECHNOLOGY & APPLIED MICROBIOLOGY: Q1; ENERGY & FUELS: Q1 | V27: 是 | W27: 是 | X27: 是 | Y27: https://topj.lib.whu.edu.cn/show.asp?cat=zk&id=3976 | Z27: https://api.crossref.org/works/10.1016/j.biortech.2018.08.016 | AA27: 机构JCR栏：搜索索引可核验；原页面直连未成功；非Clarivate账户导出 | 全部Q1仅指本表全部已核实学科；无官方完整学科导出，不承诺没有未显示学科 | AB27: original_files/R03900/fulltext/fulltext__published__254540c6f1846351.pdf | AD27: https://github.com/Colliam-Vermilion/FirstCodex/blob/results/ad-oxygen-literature-20261006/results/ad-oxygen-literature-20261006/original_files/R03900/fulltext/fulltext__published__254540c6f1846351.pdf
A28: R04092 | B28: Mathematical modelling of in-situ microaerobic desulfurization of biogas from sewage sludge digestion | C28: 2018 | D28: 2018 | E28: 10.1016/j.btre.2018.e00293 | F28: 期刊文章 | G28: 1 直接向 AD 反应器或内部循环系统供氧 | H28: 是 | I28: 研究类 | J28: 是 | K28: Biotechnology Reports | L28: Biotechnology Reports | M28: 2215-017X | O28: 已取得核验全文 | P28: 是 | Q28: 当前无补充材料原件；沿用既有缺失/无附件证据，不据此认定无附件 | R28: 2024 | S28: 2025发布版（2024指标年） | V28: 待核实 | W28: 待核实 | X28: 否 | Z28: https://api.crossref.org/works/10.1016/j.btre.2018.e00293 | AA28: 2024指标年JCR分区未核实；空白不能当非Q1。需要2025发布版/2024指标年的JCR全部学科导出。 | AB28: original_files/R04092/fulltext/fulltext__published__187b868956ed3e07.pdf | AD28: https://github.com/Colliam-Vermilion/FirstCodex/blob/results/ad-oxygen-literature-20261006/results/ad-oxygen-literature-20261006/original_files/R04092/fulltext/fulltext__published__187b868956ed3e07.pdf
A29: R04177 | B29: Operating characteristics of baffled reactor under microaerobic conditions | C29: 2018 | D29: 2018 | E29: 10.5004/dwt.2018.22410 | F29: 期刊文章 | G29: 1 直接向 AD 反应器或内部循环系统供氧 | H29: 是 | I29: 研究类 | J29: 是 | K29: Desalination and Water Treatment | L29: Desalination and Water Treatment | M29: 1944-3986 | O29: 已取得核验全文 | P29: 是 | Q29: 当前无补充材料原件；沿用既有缺失/无附件证据，不据此认定无附件 | R29: 2024 | S29: 2025发布版（2024指标年） | T29: WATER RESOURCES; ENGINEERING, CHEMICAL | U29: WATER RESOURCES: Q4; ENGINEERING, CHEMICAL: Q4 | V29: 否 | W29: 否 | X29: 是 | Y29: https://topj.lib.whu.edu.cn/show.asp?cat=sci&id=5937 | Z29: https://api.crossref.org/works/10.5004/dwt.2018.22410 | AA29: 机构JCR栏：搜索索引可核验；原页面直连未成功；非Clarivate账户导出 | 全部Q1仅指本表全部已核实学科；无官方完整学科导出，不承诺没有未显示学科 | AB29: original_files/R04177/fulltext/fulltext__published__09b0de58af2ff1e6.pdf | AD29: https://github.com/Colliam-Vermilion/FirstCodex/blob/results/ad-oxygen-literature-20261006/results/ad-oxygen-literature-20261006/original_files/R04177/fulltext/fulltext__published__09b0de58af2ff1e6.pdf
A30: R04477 | B30: Aeration to Improve Biogas Production by Recalcitrant Feedstock | C30: 2019 | D30: 2019 | E30: 10.3390/environments6040044 | F30: 期刊文章 | G30: 1 直接向 AD 反应器或内部循环系统供氧 | H30: 是 | I30: 研究类 | J30: 是 | K30: Environments | L30: Environments | N30: 2076-3298 | O30: 已取得核验全文 | P30: 是 | Q30: 当前无补充材料原件；沿用既有缺失/无附件证据，不据此认定无附件 | R30: 2024 | S30: 2025发布版（2024指标年） | V30: 待核实 | W30: 待核实 | X30: 否 | Z30: https://api.crossref.org/works/10.3390/environments6040044 | AA30: 2024指标年JCR分区未核实；空白不能当非Q1。需要2025发布版/2024指标年的JCR全部学科导出。 | AB30: original_files/R04477/fulltext/fulltext__published__dc52821c42ce8476.pdf | AD30: https://github.com/Colliam-Vermilion/FirstCodex/blob/results/ad-oxygen-literature-20261006/results/ad-oxygen-literature-20261006/original_files/R04477/fulltext/fulltext__published__dc52821c42ce8476.pdf
A31: R04510 | B31: Anaerobic digestion of wastewater rich in sulfate and sulfide: effects of metallic waste addition and micro-aeration on process performance and methane production | C31: 2019 | D31: 2019 | E31: 10.1080/10934529.2019.1623597 | F31: 期刊文章 | G31: 1 直接向 AD 反应器或内部循环系统供氧 | H31: 是 | I31: 研究类 | J31: 是 | K31: JOURNAL OF ENVIRONMENTAL SCIENCE AND HEALTH PART A-TOXIC/HAZARDOUS SUBSTANCES & ENVIRONMENTAL ENGINEERING | L31: Journal of Environmental Science and Health, Part A | M31: 1093-4529 | N31: 1532-4117 | O31: 已取得核验全文 | P31: 是 | Q31: 当前无补充材料原件；沿用既有缺失/无附件证据，不据此认定无附件 | R31: 2024 | S31: 2025发布版（2024指标年） | T31: ENGINEERING, ENVIRONMENTAL; ENVIRONMENTAL SCIENCES | U31: ENGINEERING, ENVIRONMENTAL: Q4; ENVIRONMENTAL SCIENCES: Q3 | V31: 否 | W31: 否 | X31: 是 | Y31: https://topj.lib.whu.edu.cn/show.asp?cat=zk&id=4361 | Z31: https://api.crossref.org/works/10.1080/10934529.2019.1623597 | AA31: 机构JCR栏：搜索索引可核验；原页面直连未成功；非Clarivate账户导出 | 全部Q1仅指本表全部已核实学科；无官方完整学科导出，不承诺没有未显示学科 | AB31: original_files/R04510/fulltext/fulltext__version_unverified__c4520ca79e301bb6.pdf | AD31: https://github.com/Colliam-Vermilion/FirstCodex/blob/results/ad-oxygen-literature-20261006/results/ad-oxygen-literature-20261006/original_files/R04510/fulltext/fulltext__version_unverified__c4520ca79e301bb6.pdf
A32: R04786 | B32: Enhancing methane production of anaerobic sludge digestion by microaeration: Enzyme activity stimulation, semi-continuous reactor validation and microbial community analysis | C32: 2019 | D32: 2019 | E32: 10.1016/j.biortech.2019.121643 | F32: 期刊文章 | G32: 1 直接向 AD 反应器或内部循环系统供氧 | H32: 是 | I32: 研究类 | J32: 是 | K32: BIORESOURCE TECHNOLOGY | L32: Bioresource Technology | M32: 0960-8524 | O32: 已取得核验全文 | P32: 是 | Q32: 当前无补充材料原件；沿用既有缺失/无附件证据，不据此认定无附件 | R32: 2024 | S32: 2025发布版（2024指标年） | T32: AGRICULTURAL ENGINEERING; BIOTECHNOLOGY & APPLIED MICROBIOLOGY; ENERGY & FUELS | U32: AGRICULTURAL ENGINEERING: Q1; BIOTECHNOLOGY & APPLIED MICROBIOLOGY: Q1; ENERGY & FUELS: Q1 | V32: 是 | W32: 是 | X32: 是 | Y32: https://topj.lib.whu.edu.cn/show.asp?cat=zk&id=3976 | Z32: https://api.crossref.org/works/10.1016/j.biortech.2019.121643 | AA32: 机构JCR栏：搜索索引可核验；原页面直连未成功；非Clarivate账户导出 | 全部Q1仅指本表全部已核实学科；无官方完整学科导出，不承诺没有未显示学科 | AB32: original_files/R04786/fulltext/fulltext__published__ea18005b6cd10f40.pdf | AD32: https://github.com/Colliam-Vermilion/FirstCodex/blob/results/ad-oxygen-literature-20261006/results/ad-oxygen-literature-20261006/original_files/R04786/fulltext/fulltext__published__ea18005b6cd10f40.pdf
A33: R04803 | B33: Evaluation of different air dosing strategies to enhance H 2 S removal in microaerobic systems treating low-strength wastewaters | C33: 2019 | D33: 2019 | E33: 10.1080/09593330.2018.1487470 | F33: 期刊文章 | G33: 1 直接向 AD 反应器或内部循环系统供氧 | H33: 是 | I33: 研究类 | J33: 是 | K33: ENVIRONMENTAL TECHNOLOGY | L33: Environmental Technology | M33: 0959-3330 | N33: 1479-487X | O33: 已取得核验全文 | P33: 是 | Q33: 当前无补充材料原件；沿用既有缺失/无附件证据，不据此认定无附件 | R33: 2024 | S33: 2025发布版（2024指标年） | T33: ENVIRONMENTAL SCIENCES | U33: ENVIRONMENTAL SCIENCES: Q3 | V33: 否 | W33: 否 | X33: 是 | Y33: https://topj.lib.whu.edu.cn/searchxk1.asp?ordertype=desc&page=11&q=&xk=488 | Z33: https://api.crossref.org/works/10.1080/09593330.2018.1487470 | AA33: 机构2024年JCR列表栏：搜索索引可核验；原页直连未成功；仅统计已显示学科 | 全部Q1仅指本表全部已核实学科；无官方完整学科导出，不承诺没有未显示学科 | AB33: original_files/R04803/fulltext/fulltext__published__3e98d6cf0fefd5e7.pdf | AD33: https://github.com/Colliam-Vermilion/FirstCodex/blob/results/ad-oxygen-literature-20261006/results/ad-oxygen-literature-20261006/original_files/R04803/fulltext/fulltext__published__3e98d6cf0fefd5e7.pdf
A34: R04882 | B34: Influence Mechanism of Micro-Oxygenation Treatment on Dry Fermentation of Food Waste | C34: 2019 | D34: 2019 | E34: 10.1166/jbmb.2019.1823 | F34: 期刊文章 | G34: 1 直接向 AD 反应器或内部循环系统供氧 | H34: 是 | I34: 研究类 | J34: 是 | K34: Journal of Biobased Materials and Bioenergy | L34: Journal of Biobased Materials and Bioenergy | M34: 1556-6560 | O34: 未取得全文 | P34: 否 | Q34: 当前无补充材料原件；沿用既有缺失/无附件证据，不据此认定无附件 | R34: 2024 | S34: 2025发布版（2024指标年） | V34: 待核实 | W34: 待核实 | X34: 否 | Z34: https://api.crossref.org/works/10.1166/jbmb.2019.1823 | AA34: 2024指标年JCR分区未核实；空白不能当非Q1。需要2025发布版/2024指标年的JCR全部学科导出。
A35: R04899 | B35: Intermittent micro-aeration: New strategy to control volatile fatty acid accumulation in high organic loading anaerobic digestion | C35: 2019 | D35: 2019 | E35: 10.1016/j.watres.2019.115080 | F35: 期刊文章 | G35: 1 直接向 AD 反应器或内部循环系统供氧 | H35: 是 | I35: 研究类 | J35: 是 | K35: WATER RESEARCH | L35: Water Research | M35: 0043-1354 | O35: 已取得核验全文 | P35: 是 | Q35: 已取得1件原格式补充材料；其中0件唯一关联待核实；完整性未确认 | R35: 2024 | S35: 2025发布版（2024指标年） | T35: WATER RESOURCES; ENGINEERING, ENVIRONMENTAL; ENVIRONMENTAL SCIENCES | U35: WATER RESOURCES: Q1; ENGINEERING, ENVIRONMENTAL: Q1; ENVIRONMENTAL SCIENCES: Q1 | V35: 是 | W35: 是 | X35: 是 | Y35: https://topj.lib.whu.edu.cn/show.asp?cat=zk&id=3962 | Z35: https://api.crossref.org/works/10.1016/j.watres.2019.115080 | AA35: 机构JCR栏：搜索索引可核验；原页面直连未成功；非Clarivate账户导出 | 全部Q1仅指本表全部已核实学科；无官方完整学科导出，不承诺没有未显示学科 | AB35: original_files/R04899/fulltext/fulltext__published__92f0b2f1ad01522c.pdf | AC35: original_files/R04899/supplementary/supplementary__93e7e6da6f9fc16c.docx | AD35: https://github.com/Colliam-Vermilion/FirstCodex/blob/results/ad-oxygen-literature-20261006/results/ad-oxygen-literature-20261006/original_files/R04899/fulltext/fulltext__published__92f0b2f1ad01522c.pdf
A36: R05173 | B36: Submicron magnetite‐enhanced tribromophenol removal and methanogenesis under microaerobic condition | C36: 2019 | D36: 2019 | E36: 10.1002/jctb.5817 | F36: 期刊文章 | G36: 1 直接向 AD 反应器或内部循环系统供氧 | H36: 是 | I36: 研究类 | J36: 是 | K36: JOURNAL OF CHEMICAL TECHNOLOGY AND BIOTECHNOLOGY | L36: Journal of Chemical Technology &amp; Biotechnology | M36: 0268-2575 | N36: 1097-4660 | O36: 已取得核验全文 | P36: 是 | Q36: 已取得1件原格式补充材料；其中1件唯一关联待核实；完整性未确认 | R36: 2024 | S36: 2025发布版（2024指标年） | T36: BIOTECHNOLOGY & APPLIED MICROBIOLOGY; CHEMISTRY, MULTIDISCIPLINARY; ENGINEERING, CHEMICAL; ENGINEERING, ENVIRONMENTAL | U36: BIOTECHNOLOGY & APPLIED MICROBIOLOGY: Q3; CHEMISTRY, MULTIDISCIPLINARY: Q3; ENGINEERING, CHEMICAL: Q3; ENGINEERING, ENVIRONMENTAL: Q3 | V36: 否 | W36: 否 | X36: 是 | Y36: https://topj.lib.whu.edu.cn/show.asp?cat=zk&id=7182 | Z36: https://api.crossref.org/works/10.1002/jctb.5817 | AA36: 机构JCR栏：搜索索引可核验；原页面直连未成功；非Clarivate账户导出 | 全部Q1仅指本表全部已核实学科；无官方完整学科导出，不承诺没有未显示学科 | AB36: original_files/R05173/fulltext/fulltext__published__dedf2d646e952ba0.pdf | AC36: original_files/R05173/supplementary/supplementary__63ce6947f3cf6519.docx | AD36: https://github.com/Colliam-Vermilion/FirstCodex/blob/results/ad-oxygen-literature-20261006/results/ad-oxygen-literature-20261006/original_files/R05173/fulltext/fulltext__published__dedf2d646e952ba0.pdf
A37: R05319 | B37: Air Supplement as a Stimulation Approach for the In Situ Desulfurization and Methanization Enhancement of Anaerobic Digestion of Chicken Manure | C37: 2020 | D37: 2020 | E37: 10.1021/acs.energyfuels.0c01724 | F37: 期刊文章 | G37: 1 直接向 AD 反应器或内部循环系统供氧 | H37: 是 | I37: 研究类 | J37: 是 | K37: ENERGY & FUELS | L37: Energy &amp; Fuels | M37: 0887-0624 | N37: 1520-5029 | O37: 已取得核验全文 | P37: 是 | Q37: 当前无补充材料原件；沿用既有缺失/无附件证据，不据此认定无附件 | R37: 2024 | S37: 2025发布版（2024指标年） | T37: ENERGY & FUELS; ENGINEERING, CHEMICAL | U37: ENERGY & FUELS: Q2; ENGINEERING, CHEMICAL: Q1 | V37: 是 | W37: 否 | X37: 是 | Y37: https://topj.lib.whu.edu.cn/show.asp?cat=zk&id=5342 | Z37: https://api.crossref.org/works/10.1021/acs.energyfuels.0c01724 | AA37: 机构JCR栏：搜索索引可核验；原页面直连未成功；非Clarivate账户导出 | 全部Q1仅指本表全部已核实学科；无官方完整学科导出，不承诺没有未显示学科 | AB37: original_files/R05319/fulltext/fulltext__published__865dcb7f90757119.pdf | AD37: https://github.com/Colliam-Vermilion/FirstCodex/blob/results/ad-oxygen-literature-20261006/results/ad-oxygen-literature-20261006/original_files/R05319/fulltext/fulltext__published__865dcb7f90757119.pdf
A38: R05472 | B38: Comparing Hydrogen Sulfide Removal Efficiency in a Field-Scale Digester Using Microaeration and Iron Filters | C38: 2020 | D38: 2020 | E38: 10.3390/en13184793 | F38: 期刊文章 | G38: 1 直接向 AD 反应器或内部循环系统供氧 | H38: 是 | I38: 研究类 | J38: 是 | K38: Energies | L38: Energies | N38: 1996-1073 | O38: 已取得核验全文 | P38: 是 | Q38: 当前无补充材料原件；沿用既有缺失/无附件证据，不据此认定无附件 | R38: 2024 | S38: 2025发布版（2024指标年） | V38: 待核实 | W38: 待核实 | X38: 否 | Z38: https://api.crossref.org/works/10.3390/en13184793 | AA38: 2024指标年JCR分区未核实；空白不能当非Q1。需要2025发布版/2024指标年的JCR全部学科导出。 | AB38: original_files/R05472/fulltext/fulltext__published__a81227cda8f65dc0.pdf | AD38: https://github.com/Colliam-Vermilion/FirstCodex/blob/results/ad-oxygen-literature-20261006/results/ad-oxygen-literature-20261006/original_files/R05472/fulltext/fulltext__published__a81227cda8f65dc0.pdf
A39: R05511 | B39: Different micro-aeration rates facilitate production of different end-products from source-diverted blackwater | C39: 2020 | D39: 2020 | E39: 10.1016/j.watres.2020.115783 | F39: 期刊文章 | G39: 1 直接向 AD 反应器或内部循环系统供氧 | H39: 是 | I39: 研究类 | J39: 是 | K39: WATER RESEARCH | L39: Water Research | M39: 0043-1354 | O39: 已取得核验全文 | P39: 是 | Q39: 已取得1件原格式补充材料；其中0件唯一关联待核实；完整性未确认 | R39: 2024 | S39: 2025发布版（2024指标年） | T39: WATER RESOURCES; ENGINEERING, ENVIRONMENTAL; ENVIRONMENTAL SCIENCES | U39: WATER RESOURCES: Q1; ENGINEERING, ENVIRONMENTAL: Q1; ENVIRONMENTAL SCIENCES: Q1 | V39: 是 | W39: 是 | X39: 是 | Y39: https://topj.lib.whu.edu.cn/show.asp?cat=zk&id=3962 | Z39: https://api.crossref.org/works/10.1016/j.watres.2020.115783 | AA39: 机构JCR栏：搜索索引可核验；原页面直连未成功；非Clarivate账户导出 | 全部Q1仅指本表全部已核实学科；无官方完整学科导出，不承诺没有未显示学科 | AB39: original_files/R05511/fulltext/fulltext__published__f020eb6189063184.pdf | AC39: original_files/R05511/supplementary/supplementary__b434b7fc5acd7ee0.docx | AD39: https://github.com/Colliam-Vermilion/FirstCodex/blob/results/ad-oxygen-literature-20261006/results/ad-oxygen-literature-20261006/original_files/R05511/fulltext/fulltext__published__f020eb6189063184.pdf
A40: R05638 | B40: Evaluation of Microaeration and Sound to Increase Biogas Production from Poultry Litter | C40: 2020 | D40: 2020 | E40: 10.3390/environments7080062 | F40: 期刊文章 | G40: 1 直接向 AD 反应器或内部循环系统供氧 | H40: 是 | I40: 研究类 | J40: 是 | K40: Environments | L40: Environments | N40: 2076-3298 | O40: 已取得核验全文 | P40: 是 | Q40: 当前无补充材料原件；沿用既有缺失/无附件证据，不据此认定无附件 | R40: 2024 | S40: 2025发布版（2024指标年） | V40: 待核实 | W40: 待核实 | X40: 否 | Z40: https://api.crossref.org/works/10.3390/environments7080062 | AA40: 2024指标年JCR分区未核实；空白不能当非Q1。需要2025发布版/2024指标年的JCR全部学科导出。 | AB40: original_files/R05638/fulltext/fulltext__published__2e07cb1c3931c0d4.pdf | AD40: https://github.com/Colliam-Vermilion/FirstCodex/blob/results/ad-oxygen-literature-20261006/results/ad-oxygen-literature-20261006/original_files/R05638/fulltext/fulltext__published__2e07cb1c3931c0d4.pdf
...

Sheet 期刊汇总
A1: 规范期刊 | B1: ISSN | C1: eISSN | D1: 纳入记录数 | E1: 已获取核验全文数 | F1: 研究类 | G1: 综述 | H1: 其他期刊论文 | I1: JCR数据年份 | J1: JCR发布版本 | K1: 学科类别 | L1: 分区逐学科 | M1: 至少一学科Q1 | N1: 全部已核实学科均Q1 | O1: JCR核实 | P1: 查询来源 | Q1: 核验备注
A2: BIORESOURCE TECHNOLOGY | B2: 0960-8524 | D2: 82 | E2: 82 | F2: 76 | G2: 6 | H2: 0 | I2: 2024 | J2: 2025 | K2: AGRICULTURAL ENGINEERING; BIOTECHNOLOGY & APPLIED MICROBIOLOGY; ENERGY & FUELS | L2: AGRICULTURAL ENGINEERING: Q1; BIOTECHNOLOGY & APPLIED MICROBIOLOGY: Q1; ENERGY & FUELS: Q1 | M2: 是 | N2: 是 | O2: 是 | P2: https://topj.lib.whu.edu.cn/show.asp?cat=zk&id=3976 | Q2: 统一名称及印刷/电子ISSN并集；多学科按全部已核实行保留；未知不作非Q1；原期刊名异名见文献明细
A3: Chemical Engineering Journal | B3: 1385-8947 | D3: 19 | E3: 19 | F3: 19 | G3: 0 | H3: 0 | I3: 2024 | J3: 2025 | K3: ENGINEERING, CHEMICAL; ENGINEERING, ENVIRONMENTAL | L3: ENGINEERING, CHEMICAL: Q1; ENGINEERING, ENVIRONMENTAL: Q1 | M3: 是 | N3: 是 | O3: 是 | P3: https://topj.lib.whu.edu.cn/show.asp?cat=zk&id=2740 | Q3: 统一名称及印刷/电子ISSN并集；多学科按全部已核实行保留；未知不作非Q1；原期刊名异名见文献明细
A4: Waste Management | B4: 0956-053X | D4: 16 | E4: 16 | F4: 15 | G4: 1 | H4: 0 | I4: 2024 | J4: 2025 | K4: ENGINEERING, ENVIRONMENTAL; ENVIRONMENTAL SCIENCES | L4: ENGINEERING, ENVIRONMENTAL: Q1; ENVIRONMENTAL SCIENCES: Q1 | M4: 是 | N4: 是 | O4: 是 | P4: https://topj.lib.whu.edu.cn/show.asp?cat=zk&id=4000 | Q4: 统一名称及印刷/电子ISSN并集；多学科按全部已核实行保留；未知不作非Q1；原期刊名异名见文献明细
A5: WATER RESEARCH | B5: 0043-1354 | D5: 12 | E5: 12 | F5: 11 | G5: 1 | H5: 0 | I5: 2024 | J5: 2025 | K5: WATER RESOURCES; ENGINEERING, ENVIRONMENTAL; ENVIRONMENTAL SCIENCES | L5: WATER RESOURCES: Q1; ENGINEERING, ENVIRONMENTAL: Q1; ENVIRONMENTAL SCIENCES: Q1 | M5: 是 | N5: 是 | O5: 是 | P5: https://topj.lib.whu.edu.cn/show.asp?cat=zk&id=3962 | Q5: 统一名称及印刷/电子ISSN并集；多学科按全部已核实行保留；未知不作非Q1；原期刊名异名见文献明细
A6: ENVIRONMENTAL TECHNOLOGY | B6: 0959-3330 | C6: 1479-487X | D6: 9 | E6: 9 | F6: 9 | G6: 0 | H6: 0 | I6: 2024 | J6: 2025 | K6: ENVIRONMENTAL SCIENCES | L6: ENVIRONMENTAL SCIENCES: Q3 | M6: 否 | N6: 否 | O6: 是 | P6: https://topj.lib.whu.edu.cn/searchxk1.asp?ordertype=desc&page=11&q=&xk=488 | Q6: 统一名称及印刷/电子ISSN并集；多学科按全部已核实行保留；未知不作非Q1；原期刊名异名见文献明细
A7: Renewable Energy | B7: 0960-1481 | D7: 9 | E7: 9 | F7: 9 | G7: 0 | H7: 0 | I7: 2024 | J7: 2025 | K7: ENERGY & FUELS; GREEN & SUSTAINABLE SCIENCE & TECHNOLOGY | L7: ENERGY & FUELS: Q1; GREEN & SUSTAINABLE SCIENCE & TECHNOLOGY: Q1 | M7: 是 | N7: 是 | O7: 是 | P7: https://topj.lib.whu.edu.cn/show.asp?cat=sci&id=8240 | Q7: 统一名称及印刷/电子ISSN并集；多学科按全部已核实行保留；未知不作非Q1；原期刊名异名见文献明细
A8: Science of The Total Environment | B8: 0048-9697 | D8: 9 | E8: 9 | F8: 5 | G8: 4 | H8: 0 | I8: 2024 | J8: 2025 | K8: ENVIRONMENTAL SCIENCES | L8: ENVIRONMENTAL SCIENCES: Q1 | M8: 是 | N8: 是 | O8: 是 | P8: https://topj.lib.whu.edu.cn/show.asp?cat=zk&id=4001 | Q8: 统一名称及印刷/电子ISSN并集；多学科按全部已核实行保留；未知不作非Q1；原期刊名异名见文献明细
A9: Chemosphere | B9: 0045-6535 | D9: 7 | E9: 7 | F9: 7 | G9: 0 | H9: 0 | I9: 2024 | J9: 2025 | M9: 待核实 | N9: 待核实 | O9: 否 | Q9: 统一名称及印刷/电子ISSN并集；多学科按全部已核实行保留；未知不作非Q1；原期刊名异名见文献明细
A10: Journal of Environmental Management | B10: 0301-4797 | D10: 7 | E10: 7 | F10: 6 | G10: 1 | H10: 0 | I10: 2024 | J10: 2025 | K10: ENVIRONMENTAL SCIENCES | L10: ENVIRONMENTAL SCIENCES: Q1 | M10: 是 | N10: 是 | O10: 是 | P10: https://topj.lib.whu.edu.cn/show.asp?cat=sci&id=6965 | Q10: 统一名称及印刷/电子ISSN并集；多学科按全部已核实行保留；未知不作非Q1；原期刊名异名见文献明细
A11: WATER SCIENCE AND TECHNOLOGY | B11: 0273-1223 | C11: 1996-9732 | D11: 7 | E11: 7 | F11: 7 | G11: 0 | H11: 0 | I11: 2024 | J11: 2025 | K11: WATER RESOURCES; ENGINEERING, ENVIRONMENTAL; ENVIRONMENTAL SCIENCES | L11: WATER RESOURCES: Q2; ENGINEERING, ENVIRONMENTAL: Q3; ENVIRONMENTAL SCIENCES: Q3 | M11: 否 | N11: 否 | O11: 是 | P11: https://topj.lib.whu.edu.cn/search2.asp?ordertype=&page=2&q=&sea=w&searchtype=esi | Q11: 统一名称及印刷/电子ISSN并集；多学科按全部已核实行保留；未知不作非Q1；原期刊名异名见文献明细
A12: Bioresource Technology Reports | B12: 2589-014X | D12: 6 | E12: 6 | F12: 5 | G12: 1 | H12: 0 | I12: 2024 | J12: 2025 | M12: 待核实 | N12: 待核实 | O12: 否 | Q12: 统一名称及印刷/电子ISSN并集；多学科按全部已核实行保留；未知不作非Q1；原期刊名异名见文献明细
A13: Energies | C13: 1996-1073 | D13: 6 | E13: 6 | F13: 6 | G13: 0 | H13: 0 | I13: 2024 | J13: 2025 | M13: 待核实 | N13: 待核实 | O13: 否 | Q13: 统一名称及印刷/电子ISSN并集；多学科按全部已核实行保留；未知不作非Q1；原期刊名异名见文献明细
A14: Fuel | B14: 0016-2361 | D14: 6 | E14: 6 | F14: 6 | G14: 0 | H14: 0 | I14: 2024 | J14: 2025 | K14: ENERGY & FUELS; ENGINEERING, CHEMICAL | L14: ENERGY & FUELS: Q1; ENGINEERING, CHEMICAL: Q1 | M14: 是 | N14: 是 | O14: 是 | P14: https://topj.lib.whu.edu.cn/show.asp?cat=sci&id=5597 | Q14: 统一名称及印刷/电子ISSN并集；多学科按全部已核实行保留；未知不作非Q1；原期刊名异名见文献明细
A15: JOURNAL OF CLEANER PRODUCTION | B15: 0959-6526 | D15: 6 | E15: 6 | F15: 5 | G15: 1 | H15: 0 | I15: 2024 | J15: 2025 | K15: ENGINEERING, ENVIRONMENTAL; ENVIRONMENTAL SCIENCES; GREEN & SUSTAINABLE SCIENCE & TECHNOLOGY | L15: ENGINEERING, ENVIRONMENTAL: Q1; ENVIRONMENTAL SCIENCES: Q1; GREEN & SUSTAINABLE SCIENCE & TECHNOLOGY: Q1 | M15: 是 | N15: 是 | O15: 是 | P15: https://topj.lib.whu.edu.cn/show.asp?cat=esi&id=6394 | Q15: 统一名称及印刷/电子ISSN并集；多学科按全部已核实行保留；未知不作非Q1；原期刊名异名见文献明细
A16: Journal of Biobased Materials and Bioenergy | B16: 1556-6560 | D16: 5 | E16: 0 | F16: 5 | G16: 0 | H16: 0 | I16: 2024 | J16: 2025 | M16: 待核实 | N16: 待核实 | O16: 否 | Q16: 统一名称及印刷/电子ISSN并集；多学科按全部已核实行保留；未知不作非Q1；原期刊名异名见文献明细
A17: Journal of Environmental Chemical Engineering | B17: 2213-3437; 2213-2929 | D17: 5 | E17: 5 | F17: 4 | G17: 1 | H17: 0 | I17: 2024 | J17: 2025 | K17: ENGINEERING, CHEMICAL; ENGINEERING, ENVIRONMENTAL | L17: ENGINEERING, CHEMICAL: Q1; ENGINEERING, ENVIRONMENTAL: Q1 | M17: 是 | N17: 是 | O17: 是 | P17: https://topj.lib.whu.edu.cn/show.asp?cat=zk&id=5142 | Q17: 统一名称及印刷/电子ISSN并集；多学科按全部已核实行保留；未知不作非Q1；原期刊名异名见文献明细
A18: Journal of Water Process Engineering | B18: 2214-7144 | D18: 5 | E18: 5 | F18: 4 | G18: 1 | H18: 0 | I18: 2024 | J18: 2025 | K18: WATER RESOURCES; ENGINEERING, CHEMICAL; ENGINEERING, ENVIRONMENTAL | L18: WATER RESOURCES: Q1; ENGINEERING, CHEMICAL: Q1; ENGINEERING, ENVIRONMENTAL: Q2 | M18: 是 | N18: 否 | O18: 是 | P18: https://topj.lib.whu.edu.cn/show.asp?cat=sci&id=6383 | Q18: 统一名称及印刷/电子ISSN并集；多学科按全部已核实行保留；未知不作非Q1；原期刊名异名见文献明细
A19: BIOMASS & BIOENERGY | B19: 0961-9534 | D19: 4 | E19: 4 | F19: 4 | G19: 0 | H19: 0 | I19: 2024 | J19: 2025 | K19: AGRICULTURAL ENGINEERING; BIOTECHNOLOGY & APPLIED MICROBIOLOGY; ENERGY & FUELS | L19: AGRICULTURAL ENGINEERING: Q1; BIOTECHNOLOGY & APPLIED MICROBIOLOGY: Q1; ENERGY & FUELS: Q2 | M19: 是 | N19: 否 | O19: 是 | P19: https://topj.lib.whu.edu.cn/show.asp?cat=sci&id=5613 | Q19: 统一名称及印刷/电子ISSN并集；多学科按全部已核实行保留；未知不作非Q1；原期刊名异名见文献明细
A20: ENVIRONMENTAL RESEARCH | B20: 0013-9351 | D20: 4 | E20: 4 | F20: 3 | G20: 1 | H20: 0 | I20: 2024 | J20: 2025 | K20: ENVIRONMENTAL SCIENCES; PUBLIC, ENVIRONMENTAL & OCCUPATIONAL HEALTH | L20: ENVIRONMENTAL SCIENCES: Q1; PUBLIC, ENVIRONMENTAL & OCCUPATIONAL HEALTH: Q1 | M20: 是 | N20: 是 | O20: 是 | P20: https://topj.lib.whu.edu.cn/show.asp?cat=esi&id=3602 | Q20: 统一名称及印刷/电子ISSN并集；多学科按全部已核实行保留；未知不作非Q1；原期刊名异名见文献明细
A21: Fermentation | C21: 2311-5637 | D21: 4 | E21: 4 | F21: 3 | G21: 1 | H21: 0 | I21: 2024 | J21: 2025 | M21: 待核实 | N21: 待核实 | O21: 否 | Q21: 统一名称及印刷/电子ISSN并集；多学科按全部已核实行保留；未知不作非Q1；原期刊名异名见文献明细
A22: Processes | C22: 2227-9717 | D22: 4 | E22: 4 | F22: 3 | G22: 1 | H22: 0 | I22: 2024 | J22: 2025 | M22: 待核实 | N22: 待核实 | O22: 否 | Q22: 统一名称及印刷/电子ISSN并集；多学科按全部已核实行保留；未知不作非Q1；原期刊名异名见文献明细
A23: Sustainability | C23: 2071-1050 | D23: 4 | E23: 4 | F23: 4 | G23: 0 | H23: 0 | I23: 2024 | J23: 2025 | M23: 待核实 | N23: 待核实 | O23: 否 | Q23: 统一名称及印刷/电子ISSN并集；多学科按全部已核实行保留；未知不作非Q1；原期刊名异名见文献明细
A24: Waste and Biomass Valorization | B24: 1877-2641 | C24: 1877-265X | D24: 4 | E24: 4 | F24: 3 | G24: 1 | H24: 0 | I24: 2024 | J24: 2025 | K24: ENVIRONMENTAL SCIENCES | L24: ENVIRONMENTAL SCIENCES: Q3 | M24: 否 | N24: 否 | O24: 是 | P24: https://topj.lib.whu.edu.cn/show.asp?cat=zk&id=4277 | Q24: 统一名称及印刷/电子ISSN并集；多学科按全部已核实行保留；未知不作非Q1；原期刊名异名见文献明细
A25: ACS ES&T Water | B25: 2690-0637 | C25: 2690-0637 | D25: 3 | E25: 3 | F25: 3 | G25: 0 | H25: 0 | I25: 2024 | J25: 2025 | M25: 待核实 | N25: 待核实 | O25: 否 | Q25: 统一名称及印刷/电子ISSN并集；多学科按全部已核实行保留；未知不作非Q1；原期刊名异名见文献明细
A26: APPLIED MICROBIOLOGY AND BIOTECHNOLOGY | B26: 0175-7598 | C26: 1432-0614 | D26: 3 | E26: 3 | F26: 2 | G26: 1 | H26: 0 | I26: 2024 | J26: 2025 | K26: BIOTECHNOLOGY & APPLIED MICROBIOLOGY | L26: BIOTECHNOLOGY & APPLIED MICROBIOLOGY: Q1 | M26: 是 | N26: 是 | O26: 是 | P26: https://topj.lib.whu.edu.cn/searchxk1.asp?ordertype=asc&page=6&q=&xk=291 | Q26: 统一名称及印刷/电子ISSN并集；多学科按全部已核实行保留；未知不作非Q1；原期刊名异名见文献明细
A27: ENERGY & FUELS | B27: 0887-0624 | C27: 1520-5029 | D27: 3 | E27: 3 | F27: 3 | G27: 0 | H27: 0 | I27: 2024 | J27: 2025 | K27: ENERGY & FUELS; ENGINEERING, CHEMICAL | L27: ENERGY & FUELS: Q2; ENGINEERING, CHEMICAL: Q1 | M27: 是 | N27: 否 | O27: 是 | P27: https://topj.lib.whu.edu.cn/show.asp?cat=zk&id=5342 | Q27: 统一名称及印刷/电子ISSN并集；多学科按全部已核实行保留；未知不作非Q1；原期刊名异名见文献明细
A28: ENERGY CONVERSION AND MANAGEMENT | B28: 0196-8904 | D28: 3 | E28: 3 | F28: 2 | G28: 1 | H28: 0 | I28: 2024 | J28: 2025 | K28: THERMODYNAMICS; ENERGY & FUELS; MECHANICS | L28: THERMODYNAMICS: Q1; ENERGY & FUELS: Q1; MECHANICS: Q1 | M28: 是 | N28: 是 | O28: 是 | P28: https://topj.lib.whu.edu.cn/show.asp?cat=esi&id=3481 | Q28: 统一名称及印刷/电子ISSN并集；多学科按全部已核实行保留；未知不作非Q1；原期刊名异名见文献明细
A29: ENVIRONMENTAL SCIENCE & TECHNOLOGY | B29: 0013-936X | C29: 1520-5851 | D29: 3 | E29: 3 | F29: 3 | G29: 0 | H29: 0 | I29: 2024 | J29: 2025 | K29: ENGINEERING, ENVIRONMENTAL; ENVIRONMENTAL SCIENCES | L29: ENGINEERING, ENVIRONMENTAL: Q1; ENVIRONMENTAL SCIENCES: Q1 | M29: 是 | N29: 是 | O29: 是 | P29: https://topj.lib.whu.edu.cn/show.asp?cat=zk&id=3966 | Q29: 统一名称及印刷/电子ISSN并集；多学科按全部已核实行保留；未知不作非Q1；原期刊名异名见文献明细
A30: Engenharia Sanitaria e Ambiental | B30: 1413-4152 | C30: 1809-4457 | D30: 3 | E30: 3 | F30: 3 | G30: 0 | H30: 0 | I30: 2024 | J30: 2025 | M30: 待核实 | N30: 待核实 | O30: 否 | Q30: 统一名称及印刷/电子ISSN并集；多学科按全部已核实行保留；未知不作非Q1；原期刊名异名见文献明细
A31: Environments | C31: 2076-3298 | D31: 3 | E31: 3 | F31: 2 | G31: 1 | H31: 0 | I31: 2024 | J31: 2025 | M31: 待核实 | N31: 待核实 | O31: 否 | Q31: 统一名称及印刷/电子ISSN并集；多学科按全部已核实行保留；未知不作非Q1；原期刊名异名见文献明细
A32: INTERNATIONAL BIODETERIORATION & BIODEGRADATION | B32: 0964-8305 | D32: 3 | E32: 3 | F32: 3 | G32: 0 | H32: 0 | I32: 2024 | J32: 2025 | K32: BIOTECHNOLOGY & APPLIED MICROBIOLOGY; ENVIRONMENTAL SCIENCES | L32: BIOTECHNOLOGY & APPLIED MICROBIOLOGY: Q2; ENVIRONMENTAL SCIENCES: Q2 | M32: 否 | N32: 否 | O32: 是 | P32: https://topj.lib.whu.edu.cn/show.asp?cat=sci&id=7031 | Q32: 统一名称及印刷/电子ISSN并集；多学科按全部已核实行保留；未知不作非Q1；原期刊名异名见文献明细
A33: JOURNAL OF HAZARDOUS MATERIALS | B33: 0304-3894 | D33: 3 | E33: 3 | F33: 3 | G33: 0 | H33: 0 | I33: 2024 | J33: 2025 | K33: ENGINEERING, ENVIRONMENTAL; ENVIRONMENTAL SCIENCES | L33: ENGINEERING, ENVIRONMENTAL: Q1; ENVIRONMENTAL SCIENCES: Q1 | M33: 是 | N33: 是 | O33: 是 | P33: https://topj.lib.whu.edu.cn/show.asp?cat=sci&id=6955 | Q33: 统一名称及印刷/电子ISSN并集；多学科按全部已核实行保留；未知不作非Q1；原期刊名异名见文献明细
A34: PROCESS SAFETY AND ENVIRONMENTAL PROTECTION | B34: 0957-5820 | D34: 3 | E34: 3 | F34: 2 | G34: 1 | H34: 0 | I34: 2024 | J34: 2025 | K34: ENGINEERING, CHEMICAL; ENGINEERING, ENVIRONMENTAL | L34: ENGINEERING, CHEMICAL: Q1; ENGINEERING, ENVIRONMENTAL: Q1 | M34: 是 | N34: 是 | O34: 是 | P34: https://topj.lib.whu.edu.cn/show.asp?cat=zk&id=3996 | Q34: 统一名称及印刷/电子ISSN并集；多学科按全部已核实行保留；未知不作非Q1；原期刊名异名见文献明细
A35: APPLIED BIOCHEMISTRY AND BIOTECHNOLOGY | B35: 0273-2289 | C35: 1559-0291 | D35: 2 | E35: 2 | F35: 2 | G35: 0 | H35: 0 | I35: 2024 | J35: 2025 | K35: BIOCHEMISTRY & MOLECULAR BIOLOGY; BIOTECHNOLOGY & APPLIED MICROBIOLOGY | L35: BIOCHEMISTRY & MOLECULAR BIOLOGY: Q2; BIOTECHNOLOGY & APPLIED MICROBIOLOGY: Q2 | M35: 否 | N35: 否 | O35: 是 | P35: https://topj.lib.whu.edu.cn/show.asp?cat=sci&id=2805 | Q35: 统一名称及印刷/电子ISSN并集；多学科按全部已核实行保留；未知不作非Q1；原期刊名异名见文献明细
A36: BIOENERGY RESEARCH | B36: 1939-1234 | C36: 1939-1242 | D36: 2 | E36: 2 | F36: 1 | G36: 1 | H36: 0 | I36: 2024 | J36: 2025 | K36: ENERGY & FUELS; ENVIRONMENTAL SCIENCES | L36: ENERGY & FUELS: Q3; ENVIRONMENTAL SCIENCES: Q3 | M36: 否 | N36: 否 | O36: 是 | P36: https://topj.lib.whu.edu.cn/search.asp?cat=esi&ordertype=desc&page=7&q=&xk=19 | Q36: 统一名称及印刷/电子ISSN并集；多学科按全部已核实行保留；未知不作非Q1；原期刊名异名见文献明细
A37: BIOPROCESS AND BIOSYSTEMS ENGINEERING | B37: 1615-7591 | C37: 1615-7605 | D37: 2 | E37: 2 | F37: 2 | G37: 0 | H37: 0 | I37: 2024 | J37: 2025 | K37: BIOTECHNOLOGY & APPLIED MICROBIOLOGY; ENGINEERING, CHEMICAL | L37: BIOTECHNOLOGY & APPLIED MICROBIOLOGY: Q2; ENGINEERING, CHEMICAL: Q2 | M37: 否 | N37: 否 | O37: 是 | P37: https://topj.lib.whu.edu.cn/show.asp?cat=sci&id=5879 | Q37: 统一名称及印刷/电子ISSN并集；多学科按全部已核实行保留；未知不作非Q1；原期刊名异名见文献明细
A38: BIOTECHNOLOGY ADVANCES | B38: 0734-9750 | D38: 2 | E38: 2 | F38: 1 | G38: 1 | H38: 0 | I38: 2024 | J38: 2025 | K38: BIOTECHNOLOGY & APPLIED MICROBIOLOGY | L38: BIOTECHNOLOGY & APPLIED MICROBIOLOGY: Q1 | M38: 是 | N38: 是 | O38: 是 | P38: https://topj.lib.whu.edu.cn/show.asp?cat=sci&id=2745 | Q38: 统一名称及印刷/电子ISSN并集；多学科按全部已核实行保留；未知不作非Q1；原期刊名异名见文献明细
A39: Biochemical Engineering Journal | B39: 1369-703X | D39: 2 | E39: 2 | F39: 2 | G39: 0 | H39: 0 | I39: 2024 | J39: 2025 | K39: BIOTECHNOLOGY & APPLIED MICROBIOLOGY; ENGINEERING, CHEMICAL | L39: BIOTECHNOLOGY & APPLIED MICROBIOLOGY: Q2; ENGINEERING, CHEMICAL: Q2 | M39: 否 | N39: 否 | O39: 是 | P39: https://topj.lib.whu.edu.cn/show.asp?cat=sci&id=5875 | Q39: 统一名称及印刷/电子ISSN并集；多学科按全部已核实行保留；未知不作非Q1；原期刊名异名见文献明细
A40: ChemBioEng Reviews | B40: 2196-9744 | C40: 2196-9744 | D40: 2 | E40: 2 | F40: 0 | G40: 2 | H40: 0 | I40: 2024 | J40: 2025 | K40: ENGINEERING, CHEMICAL | L40: ENGINEERING, CHEMICAL: Q1 | M40: 是 | N40: 是 | O40: 是 | P40: https://topj.lib.whu.edu.cn/show.asp?cat=zk&id=5139 | Q40: 统一名称及印刷/电子ISSN并集；多学科按全部已核实行保留；未知不作非Q1；原期刊名异名见文献明细
...

Sheet 统计汇总
A1: 集合 | B1: 文献组 | C1: 目标期刊论文数 | D1: 已核实JCR分区论文数 | E1: JCR待核实论文数 | F1: 至少一个学科Q1文章数 | G1: Q1占全部目标期刊论文 | H1: Q1占已核实JCR论文 | I1: 全部已核实学科均Q1文章数 | J1: 全部已核实学科均Q1占全部目标 | K1: 全部已核实学科均Q1占已核实 | L1: JCR核实覆盖率 | M1: 至少一学科Q1期刊种数 | N1: 全部已核实学科Q1期刊种数
A2: 全部纳入目标期刊论文 | B2: 合计 | C2: =COUNTIFS('文献明细'!$J$2:$J$555,"是") -> 386 | D2: =COUNTIFS('文献明细'!$J$2:$J$555,"是",'文献明细'!$X$2:$X$555,"是") -> 272 | E2: =C2-D2 -> 114 | F2: =COUNTIFS('文献明细'!$J$2:$J$555,"是",'文献明细'!$V$2:$V$555,"是") -> 213 | G2: =IF(C2=0,"",F2/C2) -> 0.55181347 | H2: =IF(D2=0,"",F2/D2) -> 0.78308824 | I2: =COUNTIFS('文献明细'!$J$2:$J$555,"是",'文献明细'!$W$2:$W$555,"是") -> 201 | J2: =IF(C2=0,"",I2/C2) -> 0.52072539 | K2: =IF(D2=0,"",I2/D2) -> 0.73897059 | L2: =IF(C2=0,"",D2/C2) -> 0.70466321 | M2: 28 | N2: 25
A3: 全部纳入目标期刊论文 | B3: 研究类 | C3: =COUNTIFS('文献明细'!$J$2:$J$555,"是",'文献明细'!$I$2:$I$555,"研究类") -> 339 | D3: =COUNTIFS('文献明细'!$J$2:$J$555,"是",'文献明细'!$I$2:$I$555,"研究类",'文献明细'!$X$2:$X$555,"是") -> 242 | E3: =C3-D3 -> 97 | F3: =COUNTIFS('文献明细'!$J$2:$J$555,"是",'文献明细'!$I$2:$I$555,"研究类",'文献明细'!$V$2:$V$555,"是") -> 187 | G3: =IF(C3=0,"",F3/C3) -> 0.55162242 | H3: =IF(D3=0,"",F3/D3) -> 0.77272727 | I3: =COUNTIFS('文献明细'!$J$2:$J$555,"是",'文献明细'!$I$2:$I$555,"研究类",'文献明细'!$W$2:$W$555,"是") -> 176 | J3: =IF(C3=0,"",I3/C3) -> 0.51917404 | K3: =IF(D3=0,"",I3/D3) -> 0.72727273 | L3: =IF(C3=0,"",D3/C3) -> 0.71386431 | M3: 24 | N3: 21
A4: 全部纳入目标期刊论文 | B4: 综述 | C4: =COUNTIFS('文献明细'!$J$2:$J$555,"是",'文献明细'!$I$2:$I$555,"综述") -> 46 | D4: =COUNTIFS('文献明细'!$J$2:$J$555,"是",'文献明细'!$I$2:$I$555,"综述",'文献明细'!$X$2:$X$555,"是") -> 30 | E4: =C4-D4 -> 16 | F4: =COUNTIFS('文献明细'!$J$2:$J$555,"是",'文献明细'!$I$2:$I$555,"综述",'文献明细'!$V$2:$V$555,"是") -> 26 | G4: =IF(C4=0,"",F4/C4) -> 0.56521739 | H4: =IF(D4=0,"",F4/D4) -> 0.86666667 | I4: =COUNTIFS('文献明细'!$J$2:$J$555,"是",'文献明细'!$I$2:$I$555,"综述",'文献明细'!$W$2:$W$555,"是") -> 25 | J4: =IF(C4=0,"",I4/C4) -> 0.54347826 | K4: =IF(D4=0,"",I4/D4) -> 0.83333333 | L4: =IF(C4=0,"",D4/C4) -> 0.65217391 | M4: 17 | N4: 16
A5: 全部纳入目标期刊论文 | B5: 其他期刊论文 | C5: =COUNTIFS('文献明细'!$J$2:$J$555,"是",'文献明细'!$I$2:$I$555,"其他期刊论文") -> 1 | D5: =COUNTIFS('文献明细'!$J$2:$J$555,"是",'文献明细'!$I$2:$I$555,"其他期刊论文",'文献明细'!$X$2:$X$555,"是") -> 0 | E5: =C5-D5 -> 1 | F5: =COUNTIFS('文献明细'!$J$2:$J$555,"是",'文献明细'!$I$2:$I$555,"其他期刊论文",'文献明细'!$V$2:$V$555,"是") -> 0 | G5: =IF(C5=0,"",F5/C5) -> 0 | H5: =IF(D5=0,"",F5/D5) | I5: =COUNTIFS('文献明细'!$J$2:$J$555,"是",'文献明细'!$I$2:$I$555,"其他期刊论文",'文献明细'!$W$2:$W$555,"是") -> 0 | J5: =IF(C5=0,"",I5/C5) -> 0 | K5: =IF(D5=0,"",I5/D5) | L5: =IF(C5=0,"",D5/C5) -> 0 | M5: 0 | N5: 0
A6: 已取得核验全文目标期刊论文 | B6: 合计 | C6: =COUNTIFS('文献明细'!$J$2:$J$555,"是",'文献明细'!$P$2:$P$555,"是") -> 369 | D6: =COUNTIFS('文献明细'!$J$2:$J$555,"是",'文献明细'!$P$2:$P$555,"是",'文献明细'!$X$2:$X$555,"是") -> 271 | E6: =C6-D6 -> 98 | F6: =COUNTIFS('文献明细'!$J$2:$J$555,"是",'文献明细'!$P$2:$P$555,"是",'文献明细'!$V$2:$V$555,"是") -> 213 | G6: =IF(C6=0,"",F6/C6) -> 0.57723577 | H6: =IF(D6=0,"",F6/D6) -> 0.78597786 | I6: =COUNTIFS('文献明细'!$J$2:$J$555,"是",'文献明细'!$P$2:$P$555,"是",'文献明细'!$W$2:$W$555,"是") -> 201 | J6: =IF(C6=0,"",I6/C6) -> 0.54471545 | K6: =IF(D6=0,"",I6/D6) -> 0.74169742 | L6: =IF(C6=0,"",D6/C6) -> 0.73441734 | M6: 28 | N6: 25
